Workbook

Sheet retail_store_sales
A1: Transaction ID | B1: Customer ID | C1: Category | D1: Item | E1: Price Per Unit | F1: Quantity | G1: Total Spent | H1: Payment Method | I1: Location | J1: Transaction Date | K1: Discount Applied | L1: Category Code | M1: ITEM_ID | N1: PRODUCT_NAME | O1: STOCK_LEVELS | P1: DISCOUNT_AMT | Q1: DISCOUNT_PERCENT
A2: TXN_6867343 | B2: CUST_09 | C2: Patisserie | D2: Item_10_PAT | E2: 18.5 | F2: 10 | G2: 185 | H2: Digital Wallet | I2: Online | J2: 45390 | K2: =TRUE() -> TRUE | L2: =IFERROR(INDEX(CategoryCodes!$B$2:$B$9,MATCH(C2,CategoryCodes!$A$2:$A$9,0)),"") -> H | M2: =IFERROR(VALUE(MID(D2,FIND("_",D2)+1,FIND("_",D2,FIND("_",D2)+1)-FIND("_",D2)-1)),"") -> 10 | N2: =IF(OR(C2="",M2=""),"",C2&" Item "&M2) -> Patisserie Item 10 | O2: 327 | P2: =G2*Q2 -> 18.5 | Q2: =IF(K2=TRUE(),0.1,0) -> 0.1
A3: TXN_3731986 | B3: CUST_22 | C3: Milk Products | D3: Item_17_MILK | E3: 29 | F3: 9 | G3: 261 | H3: Digital Wallet | I3: Online | J3: 45130 | K3: =TRUE() -> TRUE | L3: =IFERROR(INDEX(CategoryCodes!$B$2:$B$9,MATCH(C3,CategoryCodes!$A$2:$A$9,0)),"") -> G | M3: =IFERROR(VALUE(MID(D3,FIND("_",D3)+1,FIND("_",D3,FIND("_",D3)+1)-FIND("_",D3)-1)),"") -> 17 | N3: =IF(OR(C3="",M3=""),"",C3&" Item "&M3) -> Milk Products Item 17 | O3: 57 | P3: =G3*Q3 -> 26.1 | Q3: =IF(K3=TRUE(),0.1,0) -> 0.1
A4: TXN_9303719 | B4: CUST_02 | C4: Butchers | D4: Item_12_BUT | E4: 21.5 | F4: 2 | G4: 43 | H4: Credit Card | I4: Online | J4: 44839 | K4: =FALSE() -> FALSE | L4: =IFERROR(INDEX(CategoryCodes!$B$2:$B$9,MATCH(C4,CategoryCodes!$A$2:$A$9,0)),"") -> B | M4: =IFERROR(VALUE(MID(D4,FIND("_",D4)+1,FIND("_",D4,FIND("_",D4)+1)-FIND("_",D4)-1)),"") -> 12 | N4: =IF(OR(C4="",M4=""),"",C4&" Item "&M4) -> Butchers Item 12 | O4: 12 | P4: =G4*Q4 -> 0 | Q4: =IF(K4=TRUE(),0.1,0) -> 0
A5: TXN_9458126 | B5: CUST_06 | C5: Beverages | D5: Item_16_BEV | E5: 27.5 | F5: 9 | G5: 247.5 | H5: Credit Card | I5: Online | J5: 44688 | L5: =IFERROR(INDEX(CategoryCodes!$B$2:$B$9,MATCH(C5,CategoryCodes!$A$2:$A$9,0)),"") -> A | M5: =IFERROR(VALUE(MID(D5,FIND("_",D5)+1,FIND("_",D5,FIND("_",D5)+1)-FIND("_",D5)-1)),"") -> 16 | N5: =IF(OR(C5="",M5=""),"",C5&" Item "&M5) -> Beverages Item 16 | O5: 379 | P5: =G5*Q5 -> 0 | Q5: =IF(K5=TRUE(),0.1,0) -> 0
A6: TXN_4575373 | B6: CUST_05 | C6: Food | D6: Item_6_FOOD | E6: 12.5 | F6: 7 | G6: 87.5 | H6: Digital Wallet | I6: Online | J6: 44836 | K6: =FALSE() -> FALSE | L6: =IFERROR(INDEX(CategoryCodes!$B$2:$B$9,MATCH(C6,CategoryCodes!$A$2:$A$9,0)),"") -> E | M6: =IFERROR(VALUE(MID(D6,FIND("_",D6)+1,FIND("_",D6,FIND("_",D6)+1)-FIND("_",D6)-1)),"") -> 6 | N6: =IF(OR(C6="",M6=""),"",C6&" Item "&M6) -> Food Item 6 | O6: 140 | P6: =G6*Q6 -> 0 | Q6: =IF(K6=TRUE(),0.1,0) -> 0
A7: TXN_7482416 | B7: CUST_09 | C7: Patisserie | F7: 10 | G7: 200 | H7: Credit Card | I7: Online | J7: 45260 | L7: =IFERROR(INDEX(CategoryCodes!$B$2:$B$9,MATCH(C7,CategoryCodes!$A$2:$A$9,0)),"") -> H | M7: =IFERROR(VALUE(MID(D7,FIND("_",D7)+1,FIND("_",D7,FIND("_",D7)+1)-FIND("_",D7)-1)),"") | N7: =IF(OR(C7="",M7=""),"",C7&" Item "&M7) | O7: 125 | P7: =G7*Q7 -> 0 | Q7: =IF(K7=TRUE(),0.1,0) -> 0
A8: TXN_3652209 | B8: CUST_07 | C8: Food | D8: Item_1_FOOD | E8: 5 | F8: 8 | G8: 40 | H8: Credit Card | I8: In-store | J8: 45087 | K8: =TRUE() -> TRUE | L8: =IFERROR(INDEX(CategoryCodes!$B$2:$B$9,MATCH(C8,CategoryCodes!$A$2:$A$9,0)),"") -> E | M8: =IFERROR(VALUE(MID(D8,FIND("_",D8)+1,FIND("_",D8,FIND("_",D8)+1)-FIND("_",D8)-1)),"") -> 1 | N8: =IF(OR(C8="",M8=""),"",C8&" Item "&M8) -> Food Item 1 | O8: 114 | P8: =G8*Q8 -> 4 | Q8: =IF(K8=TRUE(),0.1,0) -> 0.1
A9: TXN_1372952 | B9: CUST_21 | C9: Furniture | E9: 33.5 | H9: Digital Wallet | I9: In-store | J9: 45384 | K9: =TRUE() -> TRUE | L9: =IFERROR(INDEX(CategoryCodes!$B$2:$B$9,MATCH(C9,CategoryCodes!$A$2:$A$9,0)),"") -> F | M9: =IFERROR(VALUE(MID(D9,FIND("_",D9)+1,FIND("_",D9,FIND("_",D9)+1)-FIND("_",D9)-1)),"") | N9: =IF(OR(C9="",M9=""),"",C9&" Item "&M9) | O9: 71 | P9: =G9*Q9 -> 0 | Q9: =IF(K9=TRUE(),0.1,0) -> 0.1
A10: TXN_9728486 | B10: CUST_23 | C10: Furniture | D10: Item_16_FUR | E10: 27.5 | F10: 1 | G10: 27.5 | H10: Credit Card | I10: In-store | J10: 45042 | K10: =FALSE() -> FALSE | L10: =IFERROR(INDEX(CategoryCodes!$B$2:$B$9,MATCH(C10,CategoryCodes!$A$2:$A$9,0)),"") -> F | M10: =IFERROR(VALUE(MID(D10,FIND("_",D10)+1,FIND("_",D10,FIND("_",D10)+1)-FIND("_",D10)-1)),"") -> 16 | N10: =IF(OR(C10="",M10=""),"",C10&" Item "&M10) -> Furniture Item 16 | O10: 377 | P10: =G10*Q10 -> 0 | Q10: =IF(K10=TRUE(),0.1,0) -> 0
A11: TXN_2722661 | B11: CUST_25 | C11: Butchers | D11: Item_22_BUT | E11: 36.5 | F11: 3 | G11: 109.5 | H11: Cash | I11: Online | J11: 45365 | K11: =FALSE() -> FALSE | L11: =IFERROR(INDEX(CategoryCodes!$B$2:$B$9,MATCH(C11,CategoryCodes!$A$2:$A$9,0)),"") -> B | M11: =IFERROR(VALUE(MID(D11,FIND("_",D11)+1,FIND("_",D11,FIND("_",D11)+1)-FIND("_",D11)-1)),"") -> 22 | N11: =IF(OR(C11="",M11=""),"",C11&" Item "&M11) -> Butchers Item 22 | O11: 52 | P11: =G11*Q11 -> 0 | Q11: =IF(K11=TRUE(),0.1,0) -> 0
A12: TXN_8776416 | B12: CUST_22 | C12: Butchers | D12: Item_3_BUT | E12: 8 | F12: 9 | G12: 72 | H12: Cash | I12: In-store | J12: 45640 | K12: =TRUE() -> TRUE | L12: =IFERROR(INDEX(CategoryCodes!$B$2:$B$9,MATCH(C12,CategoryCodes!$A$2:$A$9,0)),"") -> B | M12: =IFERROR(VALUE(MID(D12,FIND("_",D12)+1,FIND("_",D12,FIND("_",D12)+1)-FIND("_",D12)-1)),"") -> 3 | N12: =IF(OR(C12="",M12=""),"",C12&" Item "&M12) -> Butchers Item 3 | O12: 346 | P12: =G12*Q12 -> 7.2 | Q12: =IF(K12=TRUE(),0.1,0) -> 0.1
A13: TXN_5422631 | B13: CUST_09 | C13: Milk Products | F13: 8 | G13: 52 | H13: Digital Wallet | I13: In-store | J13: 45669 | K13: =TRUE() -> TRUE | L13: =IFERROR(INDEX(CategoryCodes!$B$2:$B$9,MATCH(C13,CategoryCodes!$A$2:$A$9,0)),"") -> G | M13: =IFERROR(VALUE(MID(D13,FIND("_",D13)+1,FIND("_",D13,FIND("_",D13)+1)-FIND("_",D13)-1)),"") | N13: =IF(OR(C13="",M13=""),"",C13&" Item "&M13) | O13: 379 | P13: =G13*Q13 -> 5.2 | Q13: =IF(K13=TRUE(),0.1,0) -> 0.1
A14: TXN_5874772 | B14: CUST_23 | C14: Food | D14: Item_2_FOOD | E14: 6.5 | F14: 7 | G14: 45.5 | H14: Cash | I14: Online | J14: 45178 | K14: =TRUE() -> TRUE | L14: =IFERROR(INDEX(CategoryCodes!$B$2:$B$9,MATCH(C14,CategoryCodes!$A$2:$A$9,0)),"") -> E | M14: =IFERROR(VALUE(MID(D14,FIND("_",D14)+1,FIND("_",D14,FIND("_",D14)+1)-FIND("_",D14)-1)),"") -> 2 | N14: =IF(OR(C14="",M14=""),"",C14&" Item "&M14) -> Food Item 2 | O14: 456 | P14: =G14*Q14 -> 4.55 | Q14: =IF(K14=TRUE(),0.1,0) -> 0.1
A15: TXN_4413070 | B15: CUST_14 | C15: Patisserie | D15: Item_24_PAT | E15: 39.5 | F15: 6 | G15: 237 | H15: Digital Wallet | I15: In-store | J15: 44701 | K15: =FALSE() -> FALSE | L15: =IFERROR(INDEX(CategoryCodes!$B$2:$B$9,MATCH(C15,CategoryCodes!$A$2:$A$9,0)),"") -> H | M15: =IFERROR(VALUE(MID(D15,FIND("_",D15)+1,FIND("_",D15,FIND("_",D15)+1)-FIND("_",D15)-1)),"") -> 24 | N15: =IF(OR(C15="",M15=""),"",C15&" Item "&M15) -> Patisserie Item 24 | O15: 279 | P15: =G15*Q15 -> 0 | Q15: =IF(K15=TRUE(),0.1,0) -> 0
A16: TXN_2490363 | B16: CUST_09 | C16: Milk Products | D16: Item_16_MILK | E16: 27.5 | F16: 2 | G16: 55 | H16: Digital Wallet | I16: Online | J16: 44703 | L16: =IFERROR(INDEX(CategoryCodes!$B$2:$B$9,MATCH(C16,CategoryCodes!$A$2:$A$9,0)),"") -> G | M16: =IFERROR(VALUE(MID(D16,FIND("_",D16)+1,FIND("_",D16,FIND("_",D16)+1)-FIND("_",D16)-1)),"") -> 16 | N16: =IF(OR(C16="",M16=""),"",C16&" Item "&M16) -> Milk Products Item 16 | O16: 44 | P16: =G16*Q16 -> 0 | Q16: =IF(K16=TRUE(),0.1,0) -> 0
A17: TXN_1809665 | B17: CUST_14 | C17: Beverages | E17: 24.5 | H17: Credit Card | I17: In-store | J17: 44692 | L17: =IFERROR(INDEX(CategoryCodes!$B$2:$B$9,MATCH(C17,CategoryCodes!$A$2:$A$9,0)),"") -> A | M17: =IFERROR(VALUE(MID(D17,FIND("_",D17)+1,FIND("_",D17,FIND("_",D17)+1)-FIND("_",D17)-1)),"") | N17: =IF(OR(C17="",M17=""),"",C17&" Item "&M17) | O17: 302 | P17: =G17*Q17 -> 0 | Q17: =IF(K17=TRUE(),0.1,0) -> 0
A18: TXN_7563311 | B18: CUST_23 | C18: Patisserie | D18: Item_17_PAT | E18: 29 | F18: 8 | G18: 232 | H18: Cash | I18: Online | J18: 45612 | K18: =TRUE() -> TRUE | L18: =IFERROR(INDEX(CategoryCodes!$B$2:$B$9,MATCH(C18,CategoryCodes!$A$2:$A$9,0)),"") -> H | M18: =IFERROR(VALUE(MID(D18,FIND("_",D18)+1,FIND("_",D18,FIND("_",D18)+1)-FIND("_",D18)-1)),"") -> 17 | N18: =IF(OR(C18="",M18=""),"",C18&" Item "&M18) -> Patisserie Item 17 | O18: 216 | P18: =G18*Q18 -> 23.2 | Q18: =IF(K18=TRUE(),0.1,0) -> 0.1
A19: TXN_9634894 | B19: CUST_15 | C19: Milk Products | F19: 10 | G19: 275 | H19: Digital Wallet | I19: Online | J19: 44668 | L19: =IFERROR(INDEX(CategoryCodes!$B$2:$B$9,MATCH(C19,CategoryCodes!$A$2:$A$9,0)),"") -> G | M19: =IFERROR(VALUE(MID(D19,FIND("_",D19)+1,FIND("_",D19,FIND("_",D19)+1)-FIND("_",D19)-1)),"") | N19: =IF(OR(C19="",M19=""),"",C19&" Item "&M19) | O19: 16 | P19: =G19*Q19 -> 0 | Q19: =IF(K19=TRUE(),0.1,0) -> 0
A20: TXN_4396807 | B20: CUST_17 | C20: Electric household essentials | D20: Item_13_EHE | E20: 23 | F20: 1 | G20: 23 | H20: Digital Wallet | I20: In-store | J20: 44599 | K20: =FALSE() -> FALSE | L20: =IFERROR(INDEX(CategoryCodes!$B$2:$B$9,MATCH(C20,CategoryCodes!$A$2:$A$9,0)),"") -> D | M20: =IFERROR(VALUE(MID(D20,FIND("_",D20)+1,FIND("_",D20,FIND("_",D20)+1)-FIND("_",D20)-1)),"") -> 13 | N20: =IF(OR(C20="",M20=""),"",C20&" Item "&M20) -> Electric household essentials Item 13 | O20: 15 | P20: =G20*Q20 -> 0 | Q20: =IF(K20=TRUE(),0.1,0) -> 0
A21: TXN_4206593 | B21: CUST_01 | C21: Furniture | E21: 35 | H21: Digital Wallet | I21: Online | J21: 45670 | K21: =FALSE() -> FALSE | L21: =IFERROR(INDEX(CategoryCodes!$B$2:$B$9,MATCH(C21,CategoryCodes!$A$2:$A$9,0)),"") -> F | M21: =IFERROR(VALUE(MID(D21,FIND("_",D21)+1,FIND("_",D21,FIND("_",D21)+1)-FIND("_",D21)-1)),"") | N21: =IF(OR(C21="",M21=""),"",C21&" Item "&M21) | O21: 47 | P21: =G21*Q21 -> 0 | Q21: =IF(K21=TRUE(),0.1,0) -> 0
A22: TXN_9939063 | B22: CUST_14 | C22: Beverages | D22: Item_7_BEV | E22: 14 | F22: 9 | G22: 126 | H22: Digital Wallet | I22: In-store | J22: 45305 | L22: =IFERROR(INDEX(CategoryCodes!$B$2:$B$9,MATCH(C22,CategoryCodes!$A$2:$A$9,0)),"") -> A | M22: =IFERROR(VALUE(MID(D22,FIND("_",D22)+1,FIND("_",D22,FIND("_",D22)+1)-FIND("_",D22)-1)),"") -> 7 | N22: =IF(OR(C22="",M22=""),"",C22&" Item "&M22) -> Beverages Item 7 | O22: 111 | P22: =G22*Q22 -> 0 | Q22: =IF(K22=TRUE(),0.1,0) -> 0
A23: TXN_8685338 | B23: CUST_15 | C23: Milk Products | F23: 3 | G23: 105 | H23: Credit Card | I23: In-store | J23: 45228 | L23: =IFERROR(INDEX(CategoryCodes!$B$2:$B$9,MATCH(C23,CategoryCodes!$A$2:$A$9,0)),"") -> G | M23: =IFERROR(VALUE(MID(D23,FIND("_",D23)+1,FIND("_",D23,FIND("_",D23)+1)-FIND("_",D23)-1)),"") | N23: =IF(OR(C23="",M23=""),"",C23&" Item "&M23) | O23: 119 | P23: =G23*Q23 -> 0 | Q23: =IF(K23=TRUE(),0.1,0) -> 0
A24: TXN_6547964 | B24: CUST_10 | C24: Electric household essentials | D24: Item_4_EHE | E24: 9.5 | F24: 7 | G24: 66.5 | H24: Cash | I24: In-store | J24: 44788 | L24: =IFERROR(INDEX(CategoryCodes!$B$2:$B$9,MATCH(C24,CategoryCodes!$A$2:$A$9,0)),"") -> D | M24: =IFERROR(VALUE(MID(D24,FIND("_",D24)+1,FIND("_",D24,FIND("_",D24)+1)-FIND("_",D24)-1)),"") -> 4 | N24: =IF(OR(C24="",M24=""),"",C24&" Item "&M24) -> Electric household essentials Item 4 | O24: 258 | P24: =G24*Q24 -> 0 | Q24: =IF(K24=TRUE(),0.1,0) -> 0
A25: TXN_3314099 | B25: CUST_04 | C25: Food | D25: Item_10_FOOD | E25: 18.5 | F25: 1 | G25: 18.5 | H25: Cash | I25: Online | J25: 45199 | K25: =FALSE() -> FALSE | L25: =IFERROR(INDEX(CategoryCodes!$B$2:$B$9,MATCH(C25,CategoryCodes!$A$2:$A$9,0)),"") -> E | M25: =IFERROR(VALUE(MID(D25,FIND("_",D25)+1,FIND("_",D25,FIND("_",D25)+1)-FIND("_",D25)-1)),"") -> 10 | N25: =IF(OR(C25="",M25=""),"",C25&" Item "&M25) -> Food Item 10 | O25: 308 | P25: =G25*Q25 -> 0 | Q25: =IF(K25=TRUE(),0.1,0) -> 0
A26: TXN_9980736 | B26: CUST_13 | C26: Furniture | D26: Item_14_FUR | E26: 24.5 | F26: 2 | G26: 49 | H26: Cash | I26: Online | J26: 45167 | K26: =FALSE() -> FALSE | L26: =IFERROR(INDEX(CategoryCodes!$B$2:$B$9,MATCH(C26,CategoryCodes!$A$2:$A$9,0)),"") -> F | M26: =IFERROR(VALUE(MID(D26,FIND("_",D26)+1,FIND("_",D26,FIND("_",D26)+1)-FIND("_",D26)-1)),"") -> 14 | N26: =IF(OR(C26="",M26=""),"",C26&" Item "&M26) -> Furniture Item 14 | O26: 13 | P26: =G26*Q26 -> 0 | Q26: =IF(K26=TRUE(),0.1,0) -> 0
A27: TXN_3481599 | B27: CUST_05 | C27: Furniture | E27: 39.5 | H27: Cash | I27: Online | J27: 44812 | K27: =FALSE() -> FALSE | L27: =IFERROR(INDEX(CategoryCodes!$B$2:$B$9,MATCH(C27,CategoryCodes!$A$2:$A$9,0)),"") -> F | M27: =IFERROR(VALUE(MID(D27,FIND("_",D27)+1,FIND("_",D27,FIND("_",D27)+1)-FIND("_",D27)-1)),"") | N27: =IF(OR(C27="",M27=""),"",C27&" Item "&M27) | O27: 287 | P27: =G27*Q27 -> 0 | Q27: =IF(K27=TRUE(),0.1,0) -> 0
A28: TXN_9057609 | B28: CUST_18 | C28: Butchers | D28: Item_20_BUT | E28: 33.5 | F28: 4 | G28: 134 | H28: Credit Card | I28: In-store | J28: 44636 | K28: =TRUE() -> TRUE | L28: =IFERROR(INDEX(CategoryCodes!$B$2:$B$9,MATCH(C28,CategoryCodes!$A$2:$A$9,0)),"") -> B | M28: =IFERROR(VALUE(MID(D28,FIND("_",D28)+1,FIND("_",D28,FIND("_",D28)+1)-FIND("_",D28)-1)),"") -> 20 | N28: =IF(OR(C28="",M28=""),"",C28&" Item "&M28) -> Butchers Item 20 | O28: 101 | P28: =G28*Q28 -> 13.4 | Q28: =IF(K28=TRUE(),0.1,0) -> 0.1
A29: TXN_1599706 | B29: CUST_14 | C29: Furniture | D29: Item_25_FUR | E29: 41 | F29: 10 | G29: 410 | H29: Credit Card | I29: In-store | J29: 45375 | K29: =TRUE() -> TRUE | L29: =IFERROR(INDEX(CategoryCodes!$B$2:$B$9,MATCH(C29,CategoryCodes!$A$2:$A$9,0)),"") -> F | M29: =IFERROR(VALUE(MID(D29,FIND("_",D29)+1,FIND("_",D29,FIND("_",D29)+1)-FIND("_",D29)-1)),"") -> 25 | N29: =IF(OR(C29="",M29=""),"",C29&" Item "&M29) -> Furniture Item 25 | O29: 366 | P29: =G29*Q29 -> 41 | Q29: =IF(K29=TRUE(),0.1,0) -> 0.1
A30: TXN_1598860 | B30: CUST_08 | C30: Food | D30: Item_14_FOOD | E30: 24.5 | F30: 10 | G30: 245 | H30: Cash | I30: In-store | J30: 44857 | K30: =TRUE() -> TRUE | L30: =IFERROR(INDEX(CategoryCodes!$B$2:$B$9,MATCH(C30,CategoryCodes!$A$2:$A$9,0)),"") -> E | M30: =IFERROR(VALUE(MID(D30,FIND("_",D30)+1,FIND("_",D30,FIND("_",D30)+1)-FIND("_",D30)-1)),"") -> 14 | N30: =IF(OR(C30="",M30=""),"",C30&" Item "&M30) -> Food Item 14 | O30: 332 | P30: =G30*Q30 -> 24.5 | Q30: =IF(K30=TRUE(),0.1,0) -> 0.1
A31: TXN_7138501 | B31: CUST_18 | C31: Patisserie | D31: Item_22_PAT | E31: 36.5 | F31: 5 | G31: 182.5 | H31: Credit Card | I31: In-store | J31: 44630 | K31: =FALSE() -> FALSE | L31: =IFERROR(INDEX(CategoryCodes!$B$2:$B$9,MATCH(C31,CategoryCodes!$A$2:$A$9,0)),"") -> H | M31: =IFERROR(VALUE(MID(D31,FIND("_",D31)+1,FIND("_",D31,FIND("_",D31)+1)-FIND("_",D31)-1)),"") -> 22 | N31: =IF(OR(C31="",M31=""),"",C31&" Item "&M31) -> Patisserie Item 22 | O31: 359 | P31: =G31*Q31 -> 0 | Q31: =IF(K31=TRUE(),0.1,0) -> 0
A32: TXN_5444504 | B32: CUST_05 | C32: Food | D32: Item_11_FOOD | E32: 20 | F32: 10 | G32: 200 | H32: Digital Wallet | I32: Online | J32: 44677 | K32: =FALSE() -> FALSE | L32: =IFERROR(INDEX(CategoryCodes!$B$2:$B$9,MATCH(C32,CategoryCodes!$A$2:$A$9,0)),"") -> E | M32: =IFERROR(VALUE(MID(D32,FIND("_",D32)+1,FIND("_",D32,FIND("_",D32)+1)-FIND("_",D32)-1)),"") -> 11 | N32: =IF(OR(C32="",M32=""),"",C32&" Item "&M32) -> Food Item 11 | O32: 279 | P32: =G32*Q32 -> 0 | Q32: =IF(K32=TRUE(),0.1,0) -> 0
A33: TXN_4353295 | B33: CUST_22 | C33: Patisserie | D33: Item_6_PAT | E33: 12.5 | F33: 8 | G33: 100 | H33: Credit Card | I33: Online | J33: 44656 | K33: =TRUE() -> TRUE | L33: =IFERROR(INDEX(CategoryCodes!$B$2:$B$9,MATCH(C33,CategoryCodes!$A$2:$A$9,0)),"") -> H | M33: =IFERROR(VALUE(MID(D33,FIND("_",D33)+1,FIND("_",D33,FIND("_",D33)+1)-FIND("_",D33)-1)),"") -> 6 | N33: =IF(OR(C33="",M33=""),"",C33&" Item "&M33) -> Patisserie Item 6 | O33: 214 | P33: =G33*Q33 -> 10 | Q33: =IF(K33=TRUE(),0.1,0) -> 0.1
A34: TXN_1543244 | B34: CUST_20 | C34: Food | F34: 8 | G34: 196 | H34: Credit Card | I34: Online | J34: 45590 | K34: =TRUE() -> TRUE | L34: =IFERROR(INDEX(CategoryCodes!$B$2:$B$9,MATCH(C34,CategoryCodes!$A$2:$A$9,0)),"") -> E | M34: =IFERROR(VALUE(MID(D34,FIND("_",D34)+1,FIND("_",D34,FIND("_",D34)+1)-FIND("_",D34)-1)),"") | N34: =IF(OR(C34="",M34=""),"",C34&" Item "&M34) | O34: 112 | P34: =G34*Q34 -> 19.6 | Q34: =IF(K34=TRUE(),0.1,0) -> 0.1
A35: TXN_1494700 | B35: CUST_12 | C35: Electric household essentials | D35: Item_21_EHE | E35: 35 | F35: 9 | G35: 315 | H35: Credit Card | I35: In-store | J35: 45358 | L35: =IFERROR(INDEX(CategoryCodes!$B$2:$B$9,MATCH(C35,CategoryCodes!$A$2:$A$9,0)),"") -> D | M35: =IFERROR(VALUE(MID(D35,FIND("_",D35)+1,FIND("_",D35,FIND("_",D35)+1)-FIND("_",D35)-1)),"") -> 21 | N35: =IF(OR(C35="",M35=""),"",C35&" Item "&M35) -> Electric household essentials Item 21 | O35: 229 | P35: =G35*Q35 -> 0 | Q35: =IF(K35=TRUE(),0.1,0) -> 0
A36: TXN_1621497 | B36: CUST_06 | C36: Patisserie | E36: 23 | H36: Cash | I36: In-store | J36: 44975 | L36: =IFERROR(INDEX(CategoryCodes!$B$2:$B$9,MATCH(C36,CategoryCodes!$A$2:$A$9,0)),"") -> H | M36: =IFERROR(VALUE(MID(D36,FIND("_",D36)+1,FIND("_",D36,FIND("_",D36)+1)-FIND("_",D36)-1)),"") | N36: =IF(OR(C36="",M36=""),"",C36&" Item "&M36) | O36: 301 | P36: =G36*Q36 -> 0 | Q36: =IF(K36=TRUE(),0.1,0) -> 0
A37: TXN_6398436 | B37: CUST_15 | C37: Beverages | D37: Item_25_BEV | E37: 41 | F37: 7 | G37: 287 | H37: Credit Card | I37: In-store | J37: 45446 | K37: =TRUE() -> TRUE | L37: =IFERROR(INDEX(CategoryCodes!$B$2:$B$9,MATCH(C37,CategoryCodes!$A$2:$A$9,0)),"") -> A | M37: =IFERROR(VALUE(MID(D37,FIND("_",D37)+1,FIND("_",D37,FIND("_",D37)+1)-FIND("_",D37)-1)),"") -> 25 | N37: =IF(OR(C37="",M37=""),"",C37&" Item "&M37) -> Beverages Item 25 | O37: 142 | P37: =G37*Q37 -> 28.7 | Q37: =IF(K37=TRUE(),0.1,0) -> 0.1
A38: TXN_9065245 | B38: CUST_02 | C38: Food | D38: Item_23_FOOD | E38: 38 | F38: 2 | G38: 76 | H38: Digital Wallet | I38: In-store | J38: 45361 | K38: =FALSE() -> FALSE | L38: =IFERROR(INDEX(CategoryCodes!$B$2:$B$9,MATCH(C38,CategoryCodes!$A$2:$A$9,0)),"") -> E | M38: =IFERROR(VALUE(MID(D38,FIND("_",D38)+1,FIND("_",D38,FIND("_",D38)+1)-FIND("_",D38)-1)),"") -> 23 | N38: =IF(OR(C38="",M38=""),"",C38&" Item "&M38) -> Food Item 23 | O38: 414 | P38: =G38*Q38 -> 0 | Q38: =IF(K38=TRUE(),0.1,0) -> 0
A39: TXN_6963438 | B39: CUST_11 | C39: Furniture | D39: Item_10_FUR | E39: 18.5 | F39: 5 | G39: 92.5 | H39: Credit Card | I39: Online | J39: 45405 | K39: =TRUE() -> TRUE | L39: =IFERROR(INDEX(CategoryCodes!$B$2:$B$9,MATCH(C39,CategoryCodes!$A$2:$A$9,0)),"") -> F | M39: =IFERROR(VALUE(MID(D39,FIND("_",D39)+1,FIND("_",D39,FIND("_",D39)+1)-FIND("_",D39)-1)),"") -> 10 | N39: =IF(OR(C39="",M39=""),"",C39&" Item "&M39) -> Furniture Item 10 | O39: 445 | P39: =G39*Q39 -> 9.25 | Q39: =IF(K39=TRUE(),0.1,0) -> 0.1
A40: TXN_8312797 | B40: CUST_14 | C40: Beverages | D40: Item_11_BEV | E40: 20 | F40: 5 | G40: 100 | H40: Digital Wallet | I40: Online | J40: 44715 | L40: =IFERROR(INDEX(CategoryCodes!$B$2:$B$9,MATCH(C40,CategoryCodes!$A$2:$A$9,0)),"") -> A | M40: =IFERROR(VALUE(MID(D40,FIND("_",D40)+1,FIND("_",D40,FIND("_",D40)+1)-FIND("_",D40)-1)),"") -> 11 | N40: =IF(OR(C40="",M40=""),"",C40&" Item "&M40) -> Beverages Item 11 | O40: 3 | P40: =G40*Q40 -> 0 | Q40: =IF(K40=TRUE(),0.1,0) -> 0
...

Sheet CategoryCodes
A1: Category | B1: Code
A2: Beverages | B2: A
A3: Butchers | B3: B
A4: Computers and electric accessories | B4: C
A5: Electric household essentials | B5: D
A6: Food | B6: E
A7: Furniture | B7: F
A8: Milk Products | B8: G
A9: Patisserie | B9: H
